INFO 2013-10-03 19:35:10,086 views Order #100001: beginning submission process for basket #1
ERROR 2013-10-03 19:35:10,912 views Order #100001: unhandled exception while taking payment (no such table: sagepay_sagepaytransaction)
ERROR 2013-10-03 19:35:10,912 views no such table: sagepay_sagepaytransaction
Traceback (most recent call last):
  File "/Users/user/Documents/workspace/django-oscar-sagepay/django-oscar/oscar/apps/checkout/views.py", line 515, in submit
    self.handle_payment(order_number, total_incl_tax, **payment_kwargs)
  File "/Users/user/Documents/workspace/django-oscar-sagepay/sagepay/views.py", line 83, in handle_payment
    shipping_address=self.get_shipping_address()
  File "/Users/user/Documents/workspace/django-oscar-sagepay/sagepay/facade.py", line 56, in authorise
    return self.handle_response(response=response, order_number=order_number, amount=amount)
  File "/Users/user/Documents/workspace/django-oscar-sagepay/sagepay/facade.py", line 67, in handle_response
    self.record_txn(response, order_number, amount)
  File "/Users/user/Documents/workspace/django-oscar-sagepay/sagepay/facade.py", line 90, in record_txn
    response=response.get_raw_response(),
  File "/Users/user/Documents/workspace/django-oscar-sagepay/django-env/lib/python2.7/site-packages/django/db/models/manager.py", line 149, in create
    return self.get_query_set().create(**kwargs)
  File "/Users/user/Documents/workspace/django-oscar-sagepay/django-env/lib/python2.7/site-packages/django/db/models/query.py", line 416, in create
    obj.save(force_insert=True, using=self.db)
  File "/Users/user/Documents/workspace/django-oscar-sagepay/django-env/lib/python2.7/site-packages/django/db/models/base.py", line 546, in save
    force_update=force_update, update_fields=update_fields)
  File "/Users/user/Documents/workspace/django-oscar-sagepay/django-env/lib/python2.7/site-packages/django/db/models/base.py", line 650, in save_base
    result = manager._insert([self], fields=fields, return_id=update_pk, using=using, raw=raw)
  File "/Users/user/Documents/workspace/django-oscar-sagepay/django-env/lib/python2.7/site-packages/django/db/models/manager.py", line 215, in _insert
    return insert_query(self.model, objs, fields, **kwargs)
  File "/Users/user/Documents/workspace/django-oscar-sagepay/django-env/lib/python2.7/site-packages/django/db/models/query.py", line 1675, in insert_query
    return query.get_compiler(using=using).execute_sql(return_id)
  File "/Users/user/Documents/workspace/django-oscar-sagepay/django-env/lib/python2.7/site-packages/django/db/models/sql/compiler.py", line 937, in execute_sql
    cursor.execute(sql, params)
  File "/Users/user/Documents/workspace/django-oscar-sagepay/django-env/lib/python2.7/site-packages/debug_toolbar/utils/tracking/db.py", line 89, in execute
    return self.cursor.execute(sql, params)
  File "/Users/user/Documents/workspace/django-oscar-sagepay/django-env/lib/python2.7/site-packages/django/db/backends/util.py", line 41, in execute
    return self.cursor.execute(sql, params)
  File "/Users/user/Documents/workspace/django-oscar-sagepay/django-env/lib/python2.7/site-packages/django/db/backends/sqlite3/base.py", line 366, in execute
    six.reraise(utils.DatabaseError, utils.DatabaseError(*tuple(e.args)), sys.exc_info()[2])
  File "/Users/user/Documents/workspace/django-oscar-sagepay/django-env/lib/python2.7/site-packages/django/db/backends/sqlite3/base.py", line 362, in execute
    return Database.Cursor.execute(self, query, params)
DatabaseError: no such table: sagepay_sagepaytransaction
INFO 2013-10-03 19:35:44,230 views Order #100001: beginning submission process for basket #1
ERROR 2013-10-03 19:35:45,021 views Order #100001: unhandled exception while taking payment (no such table: sagepay_sagepaytransaction)
ERROR 2013-10-03 19:35:45,022 views no such table: sagepay_sagepaytransaction
Traceback (most recent call last):
  File "/Users/user/Documents/workspace/django-oscar-sagepay/django-oscar/oscar/apps/checkout/views.py", line 515, in submit
    self.handle_payment(order_number, total_incl_tax, **payment_kwargs)
  File "/Users/user/Documents/workspace/django-oscar-sagepay/sagepay/views.py", line 83, in handle_payment
    shipping_address=self.get_shipping_address()
  File "/Users/user/Documents/workspace/django-oscar-sagepay/sagepay/facade.py", line 56, in authorise
    return self.handle_response(response=response, order_number=order_number, amount=amount)
  File "/Users/user/Documents/workspace/django-oscar-sagepay/sagepay/facade.py", line 67, in handle_response
    self.record_txn(response, order_number, amount)
  File "/Users/user/Documents/workspace/django-oscar-sagepay/sagepay/facade.py", line 90, in record_txn
    response=response.get_raw_response(),
  File "/Users/user/Documents/workspace/django-oscar-sagepay/django-env/lib/python2.7/site-packages/django/db/models/manager.py", line 149, in create
    return self.get_query_set().create(**kwargs)
  File "/Users/user/Documents/workspace/django-oscar-sagepay/django-env/lib/python2.7/site-packages/django/db/models/query.py", line 416, in create
    obj.save(force_insert=True, using=self.db)
  File "/Users/user/Documents/workspace/django-oscar-sagepay/django-env/lib/python2.7/site-packages/django/db/models/base.py", line 546, in save
    force_update=force_update, update_fields=update_fields)
  File "/Users/user/Documents/workspace/django-oscar-sagepay/django-env/lib/python2.7/site-packages/django/db/models/base.py", line 650, in save_base
    result = manager._insert([self], fields=fields, return_id=update_pk, using=using, raw=raw)
  File "/Users/user/Documents/workspace/django-oscar-sagepay/django-env/lib/python2.7/site-packages/django/db/models/manager.py", line 215, in _insert
    return insert_query(self.model, objs, fields, **kwargs)
  File "/Users/user/Documents/workspace/django-oscar-sagepay/django-env/lib/python2.7/site-packages/django/db/models/query.py", line 1675, in insert_query
    return query.get_compiler(using=using).execute_sql(return_id)
  File "/Users/user/Documents/workspace/django-oscar-sagepay/django-env/lib/python2.7/site-packages/django/db/models/sql/compiler.py", line 937, in execute_sql
    cursor.execute(sql, params)
  File "/Users/user/Documents/workspace/django-oscar-sagepay/django-env/lib/python2.7/site-packages/debug_toolbar/utils/tracking/db.py", line 89, in execute
    return self.cursor.execute(sql, params)
  File "/Users/user/Documents/workspace/django-oscar-sagepay/django-env/lib/python2.7/site-packages/django/db/backends/util.py", line 41, in execute
    return self.cursor.execute(sql, params)
  File "/Users/user/Documents/workspace/django-oscar-sagepay/django-env/lib/python2.7/site-packages/django/db/backends/sqlite3/base.py", line 366, in execute
    six.reraise(utils.DatabaseError, utils.DatabaseError(*tuple(e.args)), sys.exc_info()[2])
  File "/Users/user/Documents/workspace/django-oscar-sagepay/django-env/lib/python2.7/site-packages/django/db/backends/sqlite3/base.py", line 362, in execute
    return Database.Cursor.execute(self, query, params)
DatabaseError: no such table: sagepay_sagepaytransaction
INFO 2013-10-03 19:37:22,233 views Order #100001: beginning submission process for basket #1
WARNING 2013-10-03 19:37:22,662 views Order #100001: unable to take payment (('MALFORMED', 'The BillingPostCode field is missing from the POST.')) - restoring basket
